<?xml version="1.0" ?>
<!-- =================================================================================== -->
<!-- |    This document was autogenerated by xacro from crawler.urdf.xacro             | -->
<!-- |    EDITING THIS FILE BY HAND IS NOT RECOMMENDED                                 | -->
<!-- =================================================================================== -->
<robot name="crawler">
  <!--
        To generate the correct .URDF from this XACRO file see https://answers.ros.org/question/10401/how-to-convert-xacro-file-to-urdf-file/
  -->
  <!--########### COLORS used for the links ###########-->
  <!--colors are currently implemented as macro because just defining them, as shown in the ROS tutorial, seems not to work-->
  <material name="girdle_material">
    <color rgba="0.106 0.6 0.545 1"/>
  </material>
  <material name="body_material">
    <color rgba="1 0.8235 0.298 1"/>
  </material>
  <material name="leg_material">
    <color rgba="0.878 0.471 0.333 1"/>
  </material>
  <!--########### MACRO for links and joints ###########-->
  <!-- ########### MODEL LINKS AND JOINTS ########### -->
  <link name="girdle">
    <inertial>
      <origin rpy="0 0 0" xyz="0 0 0"/>
      <mass value="0.3333333333333333"/>
      <inertia ixx="0.0010416666666666667" ixy="0" ixz="0" iyy="0.042708333333333334" iyz="0" izz="0.042708333333333334"/>
    </inertial>
    <visual>
      <origin rpy="0 0 0" xyz="0.25 0 0"/>
      <geometry>
        <sphere radius="0.0625"/>
      </geometry>
      <material name="girdle_material"/>
    </visual>
    <visual>
      <origin rpy="0 0 0" xyz="-0.25 0 0"/>
      <geometry>
        <sphere radius="0.0625"/>
      </geometry>
    </visual>
    <visual>
      <origin rpy="0 0 0" xyz="0 0 0"/>
      <geometry>
        <box size="0.0125 0.125 0.0125"/>
      </geometry>
    </visual>
    <visual>
      <origin rpy="0 0 0" xyz="0 0 0"/>
      <geometry>
        <box size="0.5 0.05 0.0125"/>
      </geometry>
    </visual>
    <collision>
      <origin rpy="0 0 0" xyz="0.25 0 0"/>
      <geometry>
        <sphere radius="0.0625"/>
      </geometry>
    </collision>
    <collision>
      <origin rpy="0 0 0" xyz="-0.25 0 0"/>
      <geometry>
        <sphere radius="0.0625"/>
      </geometry>
    </collision>
  </link>
  <link name="spine_connection_1">
    <inertial>
      <origin rpy="0 0 0" xyz="0 0 0"/>
      <mass value="0.003333333333333333"/>
      <inertia ixx="5.208333333333333e-06" ixy="0" ixz="0" iyy="5.208333333333333e-06" iyz="0" izz="5.208333333333333e-06"/>
    </inertial>
  </link>
  <link name="spine_link_1">
    <inertial>
      <origin rpy="0 0 0" xyz="-0.5 0 0"/>
      <mass value="0.3333333333333333"/>
      <inertia ixx="0.0005208333333333333" ixy="0" ixz="0" iyy="0.0005208333333333333" iyz="0" izz="0.0005208333333333333"/>
    </inertial>
    <visual>
      <origin rpy="0 0 0" xyz="-0.5 0 0"/>
      <geometry>
        <sphere radius="0.0625"/>
      </geometry>
      <material name="body_material"/>
    </visual>
    <visual>
      <origin rpy="0 0 0" xyz="-0.25 0 0"/>
      <geometry>
        <box size="0.5 0.05 0.00625"/>
      </geometry>
    </visual>
    <collision>
      <origin rpy="0 0 0" xyz="-0.5 0 0"/>
      <geometry>
        <sphere radius="0.0625"/>
      </geometry>
    </collision>
  </link>
  <joint name="spine_lateral_joint_1" type="revolute">
    <origin rpy="0 0 0" xyz="-0.25 0 0"/>
    <axis xyz="0 0 1"/>
    <parent link="girdle"/>
    <child link="spine_connection_1"/>
    <dynamics damping="0.01" friction="0.01"/>
    <limit effort="30" lower="-1.570795" upper="1.570795" velocity="1.0"/>
  </joint>
  <joint name="spine_dorsal_joint_1" type="revolute">
    <origin rpy="-1.570795 0 0" xyz="0 0 0"/>
    <axis xyz="0 0 1"/>
    <parent link="spine_connection_1"/>
    <child link="spine_link_1"/>
    <dynamics damping="0.01" friction="0.01"/>
    <limit effort="30" lower="-0.39269875" upper="0.39269875" velocity="1.0"/>
  </joint>
  <link name="spine_connection_2">
    <inertial>
      <origin rpy="0 0 0" xyz="0 0 0"/>
      <mass value="0.003333333333333333"/>
      <inertia ixx="5.208333333333333e-06" ixy="0" ixz="0" iyy="5.208333333333333e-06" iyz="0" izz="5.208333333333333e-06"/>
    </inertial>
  </link>
  <link name="spine_link_2">
    <inertial>
      <origin rpy="0 0 0" xyz="-0.5 0 0"/>
      <mass value="0.3333333333333333"/>
      <inertia ixx="0.0005208333333333333" ixy="0" ixz="0" iyy="0.0005208333333333333" iyz="0" izz="0.0005208333333333333"/>
    </inertial>
    <visual>
      <origin rpy="0 0 0" xyz="-0.5 0 0"/>
      <geometry>
        <sphere radius="0.0625"/>
      </geometry>
      <material name="body_material"/>
    </visual>
    <visual>
      <origin rpy="0 0 0" xyz="-0.25 0 0"/>
      <geometry>
        <box size="0.5 0.05 0.00625"/>
      </geometry>
    </visual>
    <collision>
      <origin rpy="0 0 0" xyz="-0.5 0 0"/>
      <geometry>
        <sphere radius="0.0625"/>
      </geometry>
    </collision>
  </link>
  <joint name="spine_lateral_joint_2" type="revolute">
    <origin rpy="1.570795 0 0" xyz="-0.5 0 0"/>
    <axis xyz="0 0 1"/>
    <parent link="spine_link_1"/>
    <child link="spine_connection_2"/>
    <dynamics damping="0.01" friction="0.01"/>
    <limit effort="30" lower="-1.570795" upper="1.570795" velocity="1.0"/>
  </joint>
  <joint name="spine_dorsal_joint_2" type="revolute">
    <origin rpy="-1.570795 0 0" xyz="0 0 0"/>
    <axis xyz="0 0 1"/>
    <parent link="spine_connection_2"/>
    <child link="spine_link_2"/>
    <dynamics damping="0.01" friction="0.01"/>
    <limit effort="30" lower="-0.39269875" upper="0.39269875" velocity="1.0"/>
  </joint>
  <link name="right_girdle_connection_1">
    <inertial>
      <origin rpy="0 0 0" xyz="0 0 0"/>
      <mass value="0.0003333333333333333"/>
      <inertia ixx="5.787037037037036e-08" ixy="0" ixz="0" iyy="5.787037037037036e-08" iyz="0" izz="5.787037037037036e-08"/>
    </inertial>
  </link>
  <!--NOTE: currently leg joints have symmetrical limits, to avoid problems deriving from having reflected reference frames-->
  <joint name="right_girdle_abduction_joint" type="revolute">
    <origin rpy="0 0 -1.570795" xyz="0 -0.0625 0"/>
    <axis xyz="0 0 1"/>
    <parent link="girdle"/>
    <child link="right_girdle_connection_1"/>
    <dynamics damping="0.01" friction="0.01"/>
    <limit effort="30" lower="-1.570795" upper="1.570795" velocity="1.0"/>
  </joint>
  <link name="right_leg">
    <inertial>
      <origin rpy="0 0 0" xyz="0.16666666666666666 0 0"/>
      <mass value="0.03333333333333333"/>
      <inertia ixx="5.787037037037036e-06" ixy="0" ixz="0" iyy="5.787037037037036e-06" iyz="0" izz="5.787037037037036e-06"/>
    </inertial>
    <visual>
      <origin rpy="0 0 0" xyz="0.16666666666666666 0 0"/>
      <geometry>
        <sphere radius="0.020833333333333332"/>
      </geometry>
      <material name="leg_material"/>
    </visual>
    <visual>
      <origin rpy="0 0 0" xyz="0.08333333333333333 0 0"/>
      <geometry>
        <box size="0.16666666666666666 0.016666666666666666 0.016666666666666666"/>
      </geometry>
    </visual>
    <collision>
      <origin rpy="0 0 0" xyz="0.16666666666666666 0 0"/>
      <geometry>
        <sphere radius="0.020833333333333332"/>
      </geometry>
    </collision>
  </link>
  <!--NOTE: currently leg joints have symmetrical limits, to avoid problems deriving from having reflected reference frames-->
  <joint name="right_girdle_flection_joint" type="revolute">
    <origin rpy="-1.570795 0 0" xyz="0 0 0"/>
    <axis xyz="0 0 1"/>
    <parent link="right_girdle_connection_1"/>
    <child link="right_leg"/>
    <dynamics damping="0.01" friction="0.01"/>
    <limit effort="30" lower="-1.570795" upper="1.570795" velocity="1.0"/>
  </joint>
  <link name="left_girdle_connection_1">
    <inertial>
      <origin rpy="0 0 0" xyz="0 0 0"/>
      <mass value="0.0003333333333333333"/>
      <inertia ixx="5.787037037037036e-08" ixy="0" ixz="0" iyy="5.787037037037036e-08" iyz="0" izz="5.787037037037036e-08"/>
    </inertial>
  </link>
  <!--NOTE: currently leg joints have symmetrical limits, to avoid problems deriving from having reflected reference frames-->
  <joint name="left_girdle_abduction_joint" type="revolute">
    <origin rpy="0 0 1.570795" xyz="0 0.0625 0"/>
    <axis xyz="0 0 1"/>
    <parent link="girdle"/>
    <child link="left_girdle_connection_1"/>
    <dynamics damping="0.01" friction="0.01"/>
    <limit effort="30" lower="-1.570795" upper="1.570795" velocity="1.0"/>
  </joint>
  <link name="left_leg">
    <inertial>
      <origin rpy="0 0 0" xyz="0.16666666666666666 0 0"/>
      <mass value="0.03333333333333333"/>
      <inertia ixx="5.787037037037036e-06" ixy="0" ixz="0" iyy="5.787037037037036e-06" iyz="0" izz="5.787037037037036e-06"/>
    </inertial>
    <visual>
      <origin rpy="0 0 0" xyz="0.16666666666666666 0 0"/>
      <geometry>
        <sphere radius="0.020833333333333332"/>
      </geometry>
      <material name="leg_material"/>
    </visual>
    <visual>
      <origin rpy="0 0 0" xyz="0.08333333333333333 0 0"/>
      <geometry>
        <box size="0.16666666666666666 0.016666666666666666 0.016666666666666666"/>
      </geometry>
    </visual>
    <collision>
      <origin rpy="0 0 0" xyz="0.16666666666666666 0 0"/>
      <geometry>
        <sphere radius="0.020833333333333332"/>
      </geometry>
    </collision>
  </link>
  <!--NOTE: currently leg joints have symmetrical limits, to avoid problems deriving from having reflected reference frames-->
  <joint name="left_girdle_flection_joint" type="revolute">
    <origin rpy="1.570795 0 0" xyz="0 0 0"/>
    <axis xyz="0 0 1"/>
    <parent link="left_girdle_connection_1"/>
    <child link="left_leg"/>
    <dynamics damping="0.01" friction="0.01"/>
    <limit effort="30" lower="-1.570795" upper="1.570795" velocity="1.0"/>
  </joint>
</robot>
