<?xml version="1.0" encoding="utf-8"?>
<!-- =================================================================================== -->
<!-- |    This document was autogenerated by xacro from crawler.urdf.xacro             | -->
<!-- |    EDITING THIS FILE BY HAND IS NOT RECOMMENDED                                 | -->
<!-- =================================================================================== -->
<robot name="crawler">
  <!--
        To generate the correct .URDF from this XACRO file see https://answers.ros.org/question/10401/how-to-convert-xacro-file-to-urdf-file/
  -->
  <!-- ########### MODEL LINKS AND JOINTS ########### -->
  <link name="girdle">
    <inertial>
      <origin rpy="0 0 0" xyz="0 0 0"/>
      <mass value="0.2"/>
      <inertia ixx="0.0008" ixy="0" ixz="0" iyy="0.0008" iyz="0" izz="0.0008"/>
    </inertial>
    <visual>
      <origin rpy="0 0 0" xyz="0 0 0"/>
      <geometry>
        <sphere radius="0.1"/>
      </geometry>
      <material name="red">
        <color rgba="1 0 0 0.5"/>
      </material>
    </visual>
    <visual>
      <origin rpy="0 0 0" xyz="0 0 0"/>
      <geometry>
        <box size="0.05 0.25 0.05"/>
      </geometry>
      <material name="visual_box_material">
        <color rgba="0.627 0.620 0.733 1.0"/>
      </material>
    </visual>
    <visual>
      <origin rpy="0 0 0" xyz="0 0 0"/>
      <geometry>
        <box size="0.25 0.05 0.05"/>
      </geometry>
      <material name="visual_box_material">
        <color rgba="0.627 0.620 0.733 1.0"/>
      </material>
    </visual>
    <collision>
      <origin rpy="0 0 0" xyz="0 0 0"/>
      <geometry>
        <sphere radius="0.1"/>
      </geometry>
    </collision>
  </link>
  <link name="spine_link_1">
    <inertial>
      <origin rpy="0 0 0" xyz="-0.2 0 0"/>
      <mass value="0.2"/>
      <inertia ixx="0.0008" ixy="0" ixz="0" iyy="0.0008" iyz="0" izz="0.0008"/>
    </inertial>
    <visual>
      <origin rpy="0 0 0" xyz="-0.2 0 0"/>
      <geometry>
        <sphere radius="0.1"/>
      </geometry>
      <material name="body_material">
        <color rgba="0.176 0.188 0.278 1.0"/>
      </material>
    </visual>
    <visual>
      <origin rpy="0 0 0" xyz="-0.1 0 0"/>
      <geometry>
        <box size="0.2 0.04 0.025"/>
      </geometry>
      <material name="visual_box_material">
        <color rgba="0.627 0.620 0.733 1.0"/>
      </material>
    </visual>
    <collision>
      <origin rpy="0 0 0" xyz="-0.2 0 0"/>
      <geometry>
        <sphere radius="0.1"/>
      </geometry>
    </collision>
  </link>
  <joint name="girdle_spine_joint" type="revolute">
    <origin rpy="0 0 0" xyz="-0.125 0 0"/>
    <axis xyz="0 0 1"/>
    <parent link="girdle"/>
    <child link="spine_link_1"/>
    <dynamics damping="0.01" friction="0.01"/>
    <limit effort="30" lower="-0.7853975" upper="0.7853975" velocity="1.0"/>
  </joint>
  <link name="spine_link_2">
    <inertial>
      <origin rpy="0 0 0" xyz="-0.2 0 0"/>
      <mass value="0.2"/>
      <inertia ixx="0.0008" ixy="0" ixz="0" iyy="0.0008" iyz="0" izz="0.0008"/>
    </inertial>
    <visual>
      <origin rpy="0 0 0" xyz="-0.2 0 0"/>
      <geometry>
        <sphere radius="0.1"/>
      </geometry>
      <material name="body_material">
        <color rgba="0.176 0.188 0.278 1.0"/>
      </material>
    </visual>
    <visual>
      <origin rpy="0 0 0" xyz="-0.1 0 0"/>
      <geometry>
        <box size="0.2 0.04 0.025"/>
      </geometry>
      <material name="visual_box_material">
        <color rgba="0.627 0.620 0.733 1.0"/>
      </material>
    </visual>
    <collision>
      <origin rpy="0 0 0" xyz="-0.2 0 0"/>
      <geometry>
        <sphere radius="0.1"/>
      </geometry>
    </collision>
  </link>
  <joint name="spine_joint_1_2" type="revolute">
    <origin rpy="0 0 0" xyz="-0.2 0 0"/>
    <axis xyz="0 0 1"/>
    <parent link="spine_link_1"/>
    <child link="spine_link_2"/>
    <dynamics damping="0.01" friction="0.01"/>
    <limit effort="30" lower="-0.7853975" upper="0.7853975" velocity="1.0"/>
  </joint>
  <link name="spine_link_3">
    <inertial>
      <origin rpy="0 0 0" xyz="-0.2 0 0"/>
      <mass value="0.2"/>
      <inertia ixx="0.0008" ixy="0" ixz="0" iyy="0.0008" iyz="0" izz="0.0008"/>
    </inertial>
    <visual>
      <origin rpy="0 0 0" xyz="-0.2 0 0"/>
      <geometry>
        <sphere radius="0.1"/>
      </geometry>
      <material name="body_material">
        <color rgba="0.176 0.188 0.278 1.0"/>
      </material>
    </visual>
    <visual>
      <origin rpy="0 0 0" xyz="-0.1 0 0"/>
      <geometry>
        <box size="0.2 0.04 0.025"/>
      </geometry>
      <material name="visual_box_material">
        <color rgba="0.627 0.620 0.733 1.0"/>
      </material>
    </visual>
    <collision>
      <origin rpy="0 0 0" xyz="-0.2 0 0"/>
      <geometry>
        <sphere radius="0.1"/>
      </geometry>
    </collision>
  </link>
  <joint name="spine_joint_2_3" type="revolute">
    <origin rpy="0 0 0" xyz="-0.2 0 0"/>
    <axis xyz="0 0 1"/>
    <parent link="spine_link_2"/>
    <child link="spine_link_3"/>
    <dynamics damping="0.01" friction="0.01"/>
    <limit effort="30" lower="-0.7853975" upper="0.7853975" velocity="1.0"/>
  </joint>
  <link name="spine_link_4">
    <inertial>
      <origin rpy="0 0 0" xyz="-0.2 0 0"/>
      <mass value="0.2"/>
      <inertia ixx="0.0008" ixy="0" ixz="0" iyy="0.0008" iyz="0" izz="0.0008"/>
    </inertial>
    <visual>
      <origin rpy="0 0 0" xyz="-0.2 0 0"/>
      <geometry>
        <sphere radius="0.1"/>
      </geometry>
      <material name="body_material">
        <color rgba="0.176 0.188 0.278 1.0"/>
      </material>
    </visual>
    <visual>
      <origin rpy="0 0 0" xyz="-0.1 0 0"/>
      <geometry>
        <box size="0.2 0.04 0.025"/>
      </geometry>
      <material name="visual_box_material">
        <color rgba="0.627 0.620 0.733 1.0"/>
      </material>
    </visual>
    <collision>
      <origin rpy="0 0 0" xyz="-0.2 0 0"/>
      <geometry>
        <sphere radius="0.1"/>
      </geometry>
    </collision>
  </link>
  <joint name="spine_joint_3_4" type="revolute">
    <origin rpy="0 0 0" xyz="-0.2 0 0"/>
    <axis xyz="0 0 1"/>
    <parent link="spine_link_3"/>
    <child link="spine_link_4"/>
    <dynamics damping="0.01" friction="0.01"/>
    <limit effort="30" lower="-0.7853975" upper="0.7853975" velocity="1.0"/>
  </joint>
  <link name="spine_link_5">
    <inertial>
      <origin rpy="0 0 0" xyz="-0.2 0 0"/>
      <mass value="0.2"/>
      <inertia ixx="0.0008" ixy="0" ixz="0" iyy="0.0008" iyz="0" izz="0.0008"/>
    </inertial>
    <visual>
      <origin rpy="0 0 0" xyz="-0.2 0 0"/>
      <geometry>
        <sphere radius="0.1"/>
      </geometry>
      <material name="body_material">
        <color rgba="0.176 0.188 0.278 1.0"/>
      </material>
    </visual>
    <visual>
      <origin rpy="0 0 0" xyz="-0.1 0 0"/>
      <geometry>
        <box size="0.2 0.04 0.025"/>
      </geometry>
      <material name="visual_box_material">
        <color rgba="0.627 0.620 0.733 1.0"/>
      </material>
    </visual>
    <collision>
      <origin rpy="0 0 0" xyz="-0.2 0 0"/>
      <geometry>
        <sphere radius="0.1"/>
      </geometry>
    </collision>
  </link>
  <joint name="spine_joint_4_5" type="revolute">
    <origin rpy="0 0 0" xyz="-0.2 0 0"/>
    <axis xyz="0 0 1"/>
    <parent link="spine_link_4"/>
    <child link="spine_link_5"/>
    <dynamics damping="0.01" friction="0.01"/>
    <limit effort="30" lower="-0.7853975" upper="0.7853975" velocity="1.0"/>
  </joint>
  <link name="right_girdle_connection_1">
    <inertial>
      <origin rpy="0 0 0" xyz="0 0 0"/>
      <mass value="0.01"/>
      <inertia ixx="0.001" ixy="0" ixz="0" iyy="0.001" iyz="0" izz="0.001"/>
    </inertial>
  </link>
  <joint name="right_girdle_flection_joint" type="revolute">
    <origin rpy="0 1.570795 -1.570795" xyz="0 -0.125 0"/>
    <axis xyz="0 0 1"/>
    <parent link="girdle"/>
    <child link="right_girdle_connection_1"/>
    <dynamics damping="0.01" friction="0.01"/>
    <limit effort="30" lower="-0.523598333333" upper="1.570795" velocity="1.0"/>
  </joint>
  <link name="right_leg">
    <inertial>
      <origin rpy="0 0 0" xyz="0.1 0 0"/>
      <mass value="0.05"/>
      <inertia ixx="5e-05" ixy="0" ixz="0" iyy="5e-05" iyz="0" izz="5e-05"/>
    </inertial>
    <visual>
      <origin rpy="0 0 0" xyz="0.1 0 0"/>
      <geometry>
        <sphere radius="0.05"/>
      </geometry>
      <material name="leg_material">
        <color rgba="0.106 0.6 0.545 1.0"/>
      </material>
    </visual>
    <visual>
      <origin rpy="0 0 0" xyz="0.05 0 0"/>
      <geometry>
        <box size="0.1 0.02 0.02"/>
      </geometry>
      <material name="visual_box_material">
        <color rgba="0.627 0.620 0.733 1.0"/>
      </material>
    </visual>
    <collision>
      <origin rpy="0 0 0" xyz="0.1 0 0"/>
      <geometry>
        <sphere radius="0.05"/>
      </geometry>
    </collision>
  </link>
  <joint name="right_girdle_abduction_joint" type="revolute">
    <origin rpy="1.570795 0 0" xyz="0 0 0"/>
    <axis xyz="0 0 1"/>
    <parent link="right_girdle_connection_1"/>
    <child link="right_leg"/>
    <dynamics damping="0.01" friction="0.01"/>
    <limit effort="30" lower="-1.570795" upper="1.570795" velocity="1.0"/>
  </joint>
  <link name="left_girdle_connection_1">
    <inertial>
      <origin rpy="0 0 0" xyz="0 0 0"/>
      <mass value="0.01"/>
      <inertia ixx="0.001" ixy="0" ixz="0" iyy="0.001" iyz="0" izz="0.001"/>
    </inertial>
  </link>
  <joint name="left_girdle_flection_joint" type="revolute">
    <origin rpy="0 1.570795 1.570795" xyz="0 0.125 0"/>
    <axis xyz="0 0 1"/>
    <parent link="girdle"/>
    <child link="left_girdle_connection_1"/>
    <dynamics damping="0.01" friction="0.01"/>
    <limit effort="30" lower="-0.523598333333" upper="1.570795" velocity="1.0"/>
  </joint>
  <link name="left_leg">
    <inertial>
      <origin rpy="0 0 0" xyz="0.1 0 0"/>
      <mass value="0.05"/>
      <inertia ixx="5e-05" ixy="0" ixz="0" iyy="5e-05" iyz="0" izz="5e-05"/>
    </inertial>
    <visual>
      <origin rpy="0 0 0" xyz="0.1 0 0"/>
      <geometry>
        <sphere radius="0.05"/>
      </geometry>
      <material name="leg_material">
        <color rgba="0.106 0.6 0.545 1.0"/>
      </material>
    </visual>
    <visual>
      <origin rpy="0 0 0" xyz="0.05 0 0"/>
      <geometry>
        <box size="0.1 0.02 0.02"/>
      </geometry>
      <material name="visual_box_material">
        <color rgba="0.627 0.620 0.733 1.0"/>
      </material>
    </visual>
    <collision>
      <origin rpy="0 0 0" xyz="0.1 0 0"/>
      <geometry>
        <sphere radius="0.05"/>
      </geometry>
    </collision>
  </link>
  <joint name="left_girdle_abduction_joint" type="revolute">
    <origin rpy="-1.570795 0 0" xyz="0 0 0"/>
    <axis xyz="0 0 1"/>
    <parent link="left_girdle_connection_1"/>
    <child link="left_leg"/>
    <dynamics damping="0.01" friction="0.01"/>
    <limit effort="30" lower="-1.570795" upper="1.570795" velocity="1.0"/>
  </joint>
</robot>
