<?xml version="1.0" encoding="utf-8"?>
<!-- =================================================================================== -->
<!-- |    This document was autogenerated by xacro from crawler.urdf.xacro             | -->
<!-- |    EDITING THIS FILE BY HAND IS NOT RECOMMENDED                                 | -->
<!-- =================================================================================== -->
<robot name="crawler">
  <!--
        To generate the correct .URDF from this XACRO file see https://answers.ros.org/question/10401/how-to-convert-xacro-file-to-urdf-file/
  -->
  <!--########### COLORS used for the links ###########-->
  <!--colors are currently implemented as macro because just defining them, as shown in the ROS tutorial, seems not to work-->
  <material name="girdle_material">
    <color rgba="0.106 0.6 0.545 1"/>
  </material>
  <material name="body_material">
    <color rgba="1 0.8235 0.298 1"/>
  </material>
  <material name="leg_material">
    <color rgba="0.878 0.471 0.333 1"/>
  </material>
  <!--########### MACRO for links and joints ###########-->
  <!-- ########### MODEL LINKS AND JOINTS ########### -->
  <link name="girdle">
    <inertial>
      <origin rpy="0 0 0" xyz="0 0 0"/>
      <mass value="0.166666666667"/>
      <inertia ixx="4.6875e-05" ixy="0" ixz="0" iyy="0.000346875" iyz="0" izz="0.000346875"/>
    </inertial>
    <visual>
      <origin rpy="0 0 0" xyz="0.03 0 0"/>
      <geometry>
        <sphere radius="0.01875"/>
      </geometry>
      <material name="girdle_material"/>
    </visual>
    <visual>
      <origin rpy="0 0 0" xyz="-0.03 0 0"/>
      <geometry>
        <sphere radius="0.01875"/>
      </geometry>
    </visual>
    <visual>
      <origin rpy="0 0 0" xyz="0 0 0"/>
      <geometry>
        <box size="0.001875 0.0375 0.001875"/>
      </geometry>
    </visual>
    <visual>
      <origin rpy="0 0 0" xyz="0 0 0"/>
      <geometry>
        <box size="0.06 0.003 0.003"/>
      </geometry>
    </visual>
    <collision>
      <origin rpy="0 0 0" xyz="0.03 0 0"/>
      <geometry>
        <sphere radius="0.01875"/>
      </geometry>
    </collision>
    <collision>
      <origin rpy="0 0 0" xyz="-0.03 0 0"/>
      <geometry>
        <sphere radius="0.01875"/>
      </geometry>
    </collision>
  </link>
  <link name="spine_connection_1">
    <inertial>
      <origin rpy="0 0 0" xyz="0 0 0"/>
      <mass value="0.00166666666667"/>
      <inertia ixx="2.34375e-07" ixy="0" ixz="0" iyy="2.34375e-07" iyz="0" izz="2.34375e-07"/>
    </inertial>
  </link>
  <link name="spine_link_1">
    <inertial>
      <origin rpy="0 0 0" xyz="-0.06 0 0"/>
      <mass value="0.166666666667"/>
      <inertia ixx="2.34375e-05" ixy="0" ixz="0" iyy="2.34375e-05" iyz="0" izz="2.34375e-05"/>
    </inertial>
    <visual>
      <origin rpy="0 0 0" xyz="-0.06 0 0"/>
      <geometry>
        <sphere radius="0.01875"/>
      </geometry>
      <material name="body_material"/>
    </visual>
    <visual>
      <origin rpy="0 0 0" xyz="-0.03 0 0"/>
      <geometry>
        <box size="0.06 0.003 0.003"/>
      </geometry>
    </visual>
    <collision>
      <origin rpy="0 0 0" xyz="-0.06 0 0"/>
      <geometry>
        <sphere radius="0.01875"/>
      </geometry>
    </collision>
  </link>
  <joint name="spine_lateral_joint_1" type="revolute">
    <origin rpy="0 0 0" xyz="-0.03 0 0"/>
    <axis xyz="0 0 1"/>
    <parent link="girdle"/>
    <child link="spine_connection_1"/>
    <dynamics damping="0.001" friction="0.001"/>
    <limit effort="30" lower="-1.570795" upper="1.570795" velocity="1.0"/>
  </joint>
  <joint name="spine_dorsal_joint_1" type="revolute">
    <origin rpy="-1.570795 0 0" xyz="0 0 0"/>
    <axis xyz="0 0 1"/>
    <parent link="spine_connection_1"/>
    <child link="spine_link_1"/>
    <dynamics damping="0.001" friction="0.001"/>
    <limit effort="30" lower="-0.39269875" upper="0.39269875" velocity="1.0"/>
  </joint>
  <link name="spine_connection_2">
    <inertial>
      <origin rpy="0 0 0" xyz="0 0 0"/>
      <mass value="0.00166666666667"/>
      <inertia ixx="2.34375e-07" ixy="0" ixz="0" iyy="2.34375e-07" iyz="0" izz="2.34375e-07"/>
    </inertial>
  </link>
  <link name="spine_link_2">
    <inertial>
      <origin rpy="0 0 0" xyz="-0.06 0 0"/>
      <mass value="0.166666666667"/>
      <inertia ixx="2.34375e-05" ixy="0" ixz="0" iyy="2.34375e-05" iyz="0" izz="2.34375e-05"/>
    </inertial>
    <visual>
      <origin rpy="0 0 0" xyz="-0.06 0 0"/>
      <geometry>
        <sphere radius="0.01875"/>
      </geometry>
      <material name="body_material"/>
    </visual>
    <visual>
      <origin rpy="0 0 0" xyz="-0.03 0 0"/>
      <geometry>
        <box size="0.06 0.003 0.003"/>
      </geometry>
    </visual>
    <collision>
      <origin rpy="0 0 0" xyz="-0.06 0 0"/>
      <geometry>
        <sphere radius="0.01875"/>
      </geometry>
    </collision>
  </link>
  <joint name="spine_lateral_joint_2" type="revolute">
    <origin rpy="1.570795 0 0" xyz="-0.06 0 0"/>
    <axis xyz="0 0 1"/>
    <parent link="spine_link_1"/>
    <child link="spine_connection_2"/>
    <dynamics damping="0.001" friction="0.001"/>
    <limit effort="30" lower="-1.570795" upper="1.570795" velocity="1.0"/>
  </joint>
  <joint name="spine_dorsal_joint_2" type="revolute">
    <origin rpy="-1.570795 0 0" xyz="0 0 0"/>
    <axis xyz="0 0 1"/>
    <parent link="spine_connection_2"/>
    <child link="spine_link_2"/>
    <dynamics damping="0.001" friction="0.001"/>
    <limit effort="30" lower="-0.39269875" upper="0.39269875" velocity="1.0"/>
  </joint>
  <link name="spine_connection_3">
    <inertial>
      <origin rpy="0 0 0" xyz="0 0 0"/>
      <mass value="0.00166666666667"/>
      <inertia ixx="2.34375e-07" ixy="0" ixz="0" iyy="2.34375e-07" iyz="0" izz="2.34375e-07"/>
    </inertial>
  </link>
  <link name="spine_link_3">
    <inertial>
      <origin rpy="0 0 0" xyz="-0.06 0 0"/>
      <mass value="0.166666666667"/>
      <inertia ixx="2.34375e-05" ixy="0" ixz="0" iyy="2.34375e-05" iyz="0" izz="2.34375e-05"/>
    </inertial>
    <visual>
      <origin rpy="0 0 0" xyz="-0.06 0 0"/>
      <geometry>
        <sphere radius="0.01875"/>
      </geometry>
      <material name="body_material"/>
    </visual>
    <visual>
      <origin rpy="0 0 0" xyz="-0.03 0 0"/>
      <geometry>
        <box size="0.06 0.003 0.003"/>
      </geometry>
    </visual>
    <collision>
      <origin rpy="0 0 0" xyz="-0.06 0 0"/>
      <geometry>
        <sphere radius="0.01875"/>
      </geometry>
    </collision>
  </link>
  <joint name="spine_lateral_joint_3" type="revolute">
    <origin rpy="1.570795 0 0" xyz="-0.06 0 0"/>
    <axis xyz="0 0 1"/>
    <parent link="spine_link_2"/>
    <child link="spine_connection_3"/>
    <dynamics damping="0.001" friction="0.001"/>
    <limit effort="30" lower="-1.570795" upper="1.570795" velocity="1.0"/>
  </joint>
  <joint name="spine_dorsal_joint_3" type="revolute">
    <origin rpy="-1.570795 0 0" xyz="0 0 0"/>
    <axis xyz="0 0 1"/>
    <parent link="spine_connection_3"/>
    <child link="spine_link_3"/>
    <dynamics damping="0.001" friction="0.001"/>
    <limit effort="30" lower="-0.39269875" upper="0.39269875" velocity="1.0"/>
  </joint>
  <link name="spine_connection_4">
    <inertial>
      <origin rpy="0 0 0" xyz="0 0 0"/>
      <mass value="0.00166666666667"/>
      <inertia ixx="2.34375e-07" ixy="0" ixz="0" iyy="2.34375e-07" iyz="0" izz="2.34375e-07"/>
    </inertial>
  </link>
  <link name="spine_link_4">
    <inertial>
      <origin rpy="0 0 0" xyz="-0.06 0 0"/>
      <mass value="0.166666666667"/>
      <inertia ixx="2.34375e-05" ixy="0" ixz="0" iyy="2.34375e-05" iyz="0" izz="2.34375e-05"/>
    </inertial>
    <visual>
      <origin rpy="0 0 0" xyz="-0.06 0 0"/>
      <geometry>
        <sphere radius="0.01875"/>
      </geometry>
      <material name="body_material"/>
    </visual>
    <visual>
      <origin rpy="0 0 0" xyz="-0.03 0 0"/>
      <geometry>
        <box size="0.06 0.003 0.003"/>
      </geometry>
    </visual>
    <collision>
      <origin rpy="0 0 0" xyz="-0.06 0 0"/>
      <geometry>
        <sphere radius="0.01875"/>
      </geometry>
    </collision>
  </link>
  <joint name="spine_lateral_joint_4" type="revolute">
    <origin rpy="1.570795 0 0" xyz="-0.06 0 0"/>
    <axis xyz="0 0 1"/>
    <parent link="spine_link_3"/>
    <child link="spine_connection_4"/>
    <dynamics damping="0.001" friction="0.001"/>
    <limit effort="30" lower="-1.570795" upper="1.570795" velocity="1.0"/>
  </joint>
  <joint name="spine_dorsal_joint_4" type="revolute">
    <origin rpy="-1.570795 0 0" xyz="0 0 0"/>
    <axis xyz="0 0 1"/>
    <parent link="spine_connection_4"/>
    <child link="spine_link_4"/>
    <dynamics damping="0.001" friction="0.001"/>
    <limit effort="30" lower="-0.39269875" upper="0.39269875" velocity="1.0"/>
  </joint>
  <link name="spine_connection_5">
    <inertial>
      <origin rpy="0 0 0" xyz="0 0 0"/>
      <mass value="0.00166666666667"/>
      <inertia ixx="2.34375e-07" ixy="0" ixz="0" iyy="2.34375e-07" iyz="0" izz="2.34375e-07"/>
    </inertial>
  </link>
  <link name="spine_link_5">
    <inertial>
      <origin rpy="0 0 0" xyz="-0.06 0 0"/>
      <mass value="0.166666666667"/>
      <inertia ixx="2.34375e-05" ixy="0" ixz="0" iyy="2.34375e-05" iyz="0" izz="2.34375e-05"/>
    </inertial>
    <visual>
      <origin rpy="0 0 0" xyz="-0.06 0 0"/>
      <geometry>
        <sphere radius="0.01875"/>
      </geometry>
      <material name="body_material"/>
    </visual>
    <visual>
      <origin rpy="0 0 0" xyz="-0.03 0 0"/>
      <geometry>
        <box size="0.06 0.003 0.003"/>
      </geometry>
    </visual>
    <collision>
      <origin rpy="0 0 0" xyz="-0.06 0 0"/>
      <geometry>
        <sphere radius="0.01875"/>
      </geometry>
    </collision>
  </link>
  <joint name="spine_lateral_joint_5" type="revolute">
    <origin rpy="1.570795 0 0" xyz="-0.06 0 0"/>
    <axis xyz="0 0 1"/>
    <parent link="spine_link_4"/>
    <child link="spine_connection_5"/>
    <dynamics damping="0.001" friction="0.001"/>
    <limit effort="30" lower="-1.570795" upper="1.570795" velocity="1.0"/>
  </joint>
  <joint name="spine_dorsal_joint_5" type="revolute">
    <origin rpy="-1.570795 0 0" xyz="0 0 0"/>
    <axis xyz="0 0 1"/>
    <parent link="spine_connection_5"/>
    <child link="spine_link_5"/>
    <dynamics damping="0.001" friction="0.001"/>
    <limit effort="30" lower="-0.39269875" upper="0.39269875" velocity="1.0"/>
  </joint>
  <link name="right_girdle_connection_1">
    <inertial>
      <origin rpy="0 0 0" xyz="0 0 0"/>
      <mass value="0.000166666666667"/>
      <inertia ixx="2.60416666667e-09" ixy="0" ixz="0" iyy="2.60416666667e-09" iyz="0" izz="2.60416666667e-09"/>
    </inertial>
  </link>
  <!--NOTE: currently leg joints have symmetrical limits, to avoid problems deriving from having reflected reference frames-->
  <joint name="right_girdle_abduction_joint" type="revolute">
    <origin rpy="0 0 -1.570795" xyz="0 -0.01875 0"/>
    <axis xyz="0 0 1"/>
    <parent link="girdle"/>
    <child link="right_girdle_connection_1"/>
    <dynamics damping="0.001" friction="0.001"/>
    <limit effort="30" lower="-1.570795" upper="1.570795" velocity="1.0"/>
  </joint>
  <link name="right_leg">
    <inertial>
      <origin rpy="0 0 0" xyz="0.0375 0 0"/>
      <mass value="0.0166666666667"/>
      <inertia ixx="2.60416666667e-07" ixy="0" ixz="0" iyy="2.60416666667e-07" iyz="0" izz="2.60416666667e-07"/>
    </inertial>
    <visual>
      <origin rpy="0 0 0" xyz="0.0375 0 0"/>
      <geometry>
        <sphere radius="0.00625"/>
      </geometry>
      <material name="leg_material"/>
    </visual>
    <visual>
      <origin rpy="0 0 0" xyz="0.01875 0 0"/>
      <geometry>
        <box size="0.0375 0.001875 0.001875"/>
      </geometry>
    </visual>
    <collision>
      <origin rpy="0 0 0" xyz="0.0375 0 0"/>
      <geometry>
        <sphere radius="0.00625"/>
      </geometry>
    </collision>
  </link>
  <!--NOTE: currently leg joints have symmetrical limits, to avoid problems deriving from having reflected reference frames-->
  <joint name="right_girdle_flection_joint" type="revolute">
    <origin rpy="-1.570795 0 0" xyz="0 0 0"/>
    <axis xyz="0 0 1"/>
    <parent link="right_girdle_connection_1"/>
    <child link="right_leg"/>
    <dynamics damping="0.001" friction="0.001"/>
    <limit effort="30" lower="-0.523598333333" upper="0.523598333333" velocity="1.0"/>
  </joint>
  <link name="left_girdle_connection_1">
    <inertial>
      <origin rpy="0 0 0" xyz="0 0 0"/>
      <mass value="0.000166666666667"/>
      <inertia ixx="2.60416666667e-09" ixy="0" ixz="0" iyy="2.60416666667e-09" iyz="0" izz="2.60416666667e-09"/>
    </inertial>
  </link>
  <!--NOTE: currently leg joints have symmetrical limits, to avoid problems deriving from having reflected reference frames-->
  <joint name="left_girdle_abduction_joint" type="revolute">
    <origin rpy="0 0 1.570795" xyz="0 0.01875 0"/>
    <axis xyz="0 0 1"/>
    <parent link="girdle"/>
    <child link="left_girdle_connection_1"/>
    <dynamics damping="0.001" friction="0.001"/>
    <limit effort="30" lower="-1.570795" upper="1.570795" velocity="1.0"/>
  </joint>
  <link name="left_leg">
    <inertial>
      <origin rpy="0 0 0" xyz="0.0375 0 0"/>
      <mass value="0.0166666666667"/>
      <inertia ixx="2.60416666667e-07" ixy="0" ixz="0" iyy="2.60416666667e-07" iyz="0" izz="2.60416666667e-07"/>
    </inertial>
    <visual>
      <origin rpy="0 0 0" xyz="0.0375 0 0"/>
      <geometry>
        <sphere radius="0.00625"/>
      </geometry>
      <material name="leg_material"/>
    </visual>
    <visual>
      <origin rpy="0 0 0" xyz="0.01875 0 0"/>
      <geometry>
        <box size="0.0375 0.001875 0.001875"/>
      </geometry>
    </visual>
    <collision>
      <origin rpy="0 0 0" xyz="0.0375 0 0"/>
      <geometry>
        <sphere radius="0.00625"/>
      </geometry>
    </collision>
  </link>
  <!--NOTE: currently leg joints have symmetrical limits, to avoid problems deriving from having reflected reference frames-->
  <joint name="left_girdle_flection_joint" type="revolute">
    <origin rpy="1.570795 0 0" xyz="0 0 0"/>
    <axis xyz="0 0 1"/>
    <parent link="left_girdle_connection_1"/>
    <child link="left_leg"/>
    <dynamics damping="0.001" friction="0.001"/>
    <limit effort="30" lower="-0.523598333333" upper="0.523598333333" velocity="1.0"/>
  </joint>
</robot>
