<?xml version="1.0" encoding="utf-8"?>
<!-- =================================================================================== -->
<!-- |    This document was autogenerated by xacro from crawler.urdf.xacro             | -->
<!-- |    EDITING THIS FILE BY HAND IS NOT RECOMMENDED                                 | -->
<!-- =================================================================================== -->
<robot name="crawler">
  <!--
        To generate the correct .URDF from this XACRO file see https://answers.ros.org/question/10401/how-to-convert-xacro-file-to-urdf-file/
  -->
  <!--########### COLORS used for the links ###########-->
  <!--colors are currently implemented as macro because just defining them, as shown in the ROS tutorial, seems not to work-->
  <material name="girdle_material">
    <color rgba="0.106 0.6 0.545 1"/>
  </material>
  <material name="body_material">
    <color rgba="1 0.8235 0.298 1"/>
  </material>
  <material name="leg_material">
    <color rgba="0.878 0.471 0.333 1"/>
  </material>
  <!--########### MACRO for links and joints ###########-->
  <!-- ########### MODEL LINKS AND JOINTS ########### -->
  <link name="girdle">
    <inertial>
      <origin rpy="0 0 0" xyz="0 0 0"/>
      <mass value="0.000794"/>
      <inertia ixx="7.22e-09" ixy="0" ixz="0" iyy="1.345e-07" iyz="0" izz="1.345e-07"/>
    </inertial>
    <visual>
      <origin rpy="0 0 0" xyz="0.0108571428571 0 0"/>
      <geometry>
        <sphere radius="0.00475"/>
      </geometry>
      <material name="girdle_material"/>
    </visual>
    <visual>
      <origin rpy="0 0 0" xyz="-0.0108571428571 0 0"/>
      <geometry>
        <sphere radius="0.00475"/>
      </geometry>
    </visual>
    <visual>
      <origin rpy="0 0 0" xyz="0 0 0"/>
      <geometry>
        <box size="0.000542857142857 0.0108571428571 0.000542857142857"/>
      </geometry>
    </visual>
    <visual>
      <origin rpy="0 0 0" xyz="0 0 0"/>
      <geometry>
        <box size="0.0217142857143 0.00108571428571 0.00108571428571"/>
      </geometry>
    </visual>
    <collision>
      <origin rpy="0 0 0" xyz="0.0108571428571 0 0"/>
      <geometry>
        <sphere radius="0.00475"/>
      </geometry>
    </collision>
    <collision>
      <origin rpy="0 0 0" xyz="-0.0108571428571 0 0"/>
      <geometry>
        <sphere radius="0.00475"/>
      </geometry>
    </collision>
  </link>
  <link name="spine_connection_1">
    <inertial>
      <origin rpy="0 0 0" xyz="0 0 0"/>
      <mass value="4e-06"/>
      <inertia ixx="3.61e-11" ixy="0" ixz="0" iyy="3.61e-11" iyz="0" izz="3.61e-11"/>
    </inertial>
  </link>
  <link name="spine_link_1">
    <inertial>
      <origin rpy="0 0 0" xyz="-0.0108571428571 0 0"/>
      <mass value="0.0006294"/>
      <inertia ixx="5.68e-09" ixy="0" ixz="0" iyy="5.68e-09" iyz="0" izz="5.68e-09"/>
    </inertial>
    <visual>
      <origin rpy="0 0 0" xyz="-0.0108571428571 0 0"/>
      <geometry>
        <sphere radius="0.00475"/>
      </geometry>
      <material name="body_material"/>
    </visual>
    <visual>
      <origin rpy="0 0 0" xyz="-0.00542857142857 0 0"/>
      <geometry>
        <box size="0.0108571428571 0.000542857142857 0.000542857142857"/>
      </geometry>
    </visual>
    <collision>
      <origin rpy="0 0 0" xyz="-0.0108571428571 0 0"/>
      <geometry>
        <sphere radius="0.00475"/>
      </geometry>
    </collision>
  </link>
  <joint name="spine_lateral_joint_1" type="revolute">
    <origin rpy="0 0 0" xyz="-0.0108571428571 0 0"/>
    <axis xyz="0 0 1"/>
    <parent link="girdle"/>
    <child link="spine_connection_1"/>
    <dynamics damping="0.0" friction="0.0"/>
    <limit effort="30" lower="-1.570795" upper="1.570795" velocity="1.0"/>
  </joint>
  <joint name="spine_dorsal_joint_1" type="revolute">
    <origin rpy="-1.570795 0 0" xyz="0 0 0"/>
    <axis xyz="0 0 1"/>
    <parent link="spine_connection_1"/>
    <child link="spine_link_1"/>
    <dynamics damping="0.0" friction="0.0"/>
    <limit effort="30" lower="-0.39269875" upper="0.39269875" velocity="1.0"/>
  </joint>
  <link name="spine_connection_2">
    <inertial>
      <origin rpy="0 0 0" xyz="0 0 0"/>
      <mass value="4e-06"/>
      <inertia ixx="3.61e-11" ixy="0" ixz="0" iyy="3.61e-11" iyz="0" izz="3.61e-11"/>
    </inertial>
  </link>
  <link name="spine_link_2">
    <inertial>
      <origin rpy="0 0 0" xyz="-0.0108571428571 0 0"/>
      <mass value="0.0005857"/>
      <inertia ixx="5.286e-09" ixy="0" ixz="0" iyy="5.286e-09" iyz="0" izz="5.286e-09"/>
    </inertial>
    <visual>
      <origin rpy="0 0 0" xyz="-0.0108571428571 0 0"/>
      <geometry>
        <sphere radius="0.00475"/>
      </geometry>
      <material name="body_material"/>
    </visual>
    <visual>
      <origin rpy="0 0 0" xyz="-0.00542857142857 0 0"/>
      <geometry>
        <box size="0.0108571428571 0.000542857142857 0.000542857142857"/>
      </geometry>
    </visual>
    <collision>
      <origin rpy="0 0 0" xyz="-0.0108571428571 0 0"/>
      <geometry>
        <sphere radius="0.00475"/>
      </geometry>
    </collision>
  </link>
  <joint name="spine_lateral_joint_2" type="revolute">
    <origin rpy="1.570795 0 0" xyz="-0.0108571428571 0 0"/>
    <axis xyz="0 0 1"/>
    <parent link="spine_link_1"/>
    <child link="spine_connection_2"/>
    <dynamics damping="0.0" friction="0.0"/>
    <limit effort="30" lower="-1.570795" upper="1.570795" velocity="1.0"/>
  </joint>
  <joint name="spine_dorsal_joint_2" type="revolute">
    <origin rpy="-1.570795 0 0" xyz="0 0 0"/>
    <axis xyz="0 0 1"/>
    <parent link="spine_connection_2"/>
    <child link="spine_link_2"/>
    <dynamics damping="0.0" friction="0.0"/>
    <limit effort="30" lower="-0.39269875" upper="0.39269875" velocity="1.0"/>
  </joint>
  <link name="spine_connection_3">
    <inertial>
      <origin rpy="0 0 0" xyz="0 0 0"/>
      <mass value="4e-06"/>
      <inertia ixx="3.61e-11" ixy="0" ixz="0" iyy="3.61e-11" iyz="0" izz="3.61e-11"/>
    </inertial>
  </link>
  <link name="spine_link_3">
    <inertial>
      <origin rpy="0 0 0" xyz="-0.0108571428571 0 0"/>
      <mass value="0.0004432"/>
      <inertia ixx="4e-09" ixy="0" ixz="0" iyy="4e-09" iyz="0" izz="4e-09"/>
    </inertial>
    <visual>
      <origin rpy="0 0 0" xyz="-0.0108571428571 0 0"/>
      <geometry>
        <sphere radius="0.00475"/>
      </geometry>
      <material name="body_material"/>
    </visual>
    <visual>
      <origin rpy="0 0 0" xyz="-0.00542857142857 0 0"/>
      <geometry>
        <box size="0.0108571428571 0.000542857142857 0.000542857142857"/>
      </geometry>
    </visual>
    <collision>
      <origin rpy="0 0 0" xyz="-0.0108571428571 0 0"/>
      <geometry>
        <sphere radius="0.00475"/>
      </geometry>
    </collision>
  </link>
  <joint name="spine_lateral_joint_3" type="revolute">
    <origin rpy="1.570795 0 0" xyz="-0.0108571428571 0 0"/>
    <axis xyz="0 0 1"/>
    <parent link="spine_link_2"/>
    <child link="spine_connection_3"/>
    <dynamics damping="0.0" friction="0.0"/>
    <limit effort="30" lower="-1.570795" upper="1.570795" velocity="1.0"/>
  </joint>
  <joint name="spine_dorsal_joint_3" type="revolute">
    <origin rpy="-1.570795 0 0" xyz="0 0 0"/>
    <axis xyz="0 0 1"/>
    <parent link="spine_connection_3"/>
    <child link="spine_link_3"/>
    <dynamics damping="0.0" friction="0.0"/>
    <limit effort="30" lower="-0.39269875" upper="0.39269875" velocity="1.0"/>
  </joint>
  <link name="spine_connection_4">
    <inertial>
      <origin rpy="0 0 0" xyz="0 0 0"/>
      <mass value="4e-06"/>
      <inertia ixx="3.61e-11" ixy="0" ixz="0" iyy="3.61e-11" iyz="0" izz="3.61e-11"/>
    </inertial>
  </link>
  <link name="spine_link_4">
    <inertial>
      <origin rpy="0 0 0" xyz="-0.0108571428571 0 0"/>
      <mass value="0.0002397"/>
      <inertia ixx="2.16e-09" ixy="0" ixz="0" iyy="2.16e-09" iyz="0" izz="2.16e-09"/>
    </inertial>
    <visual>
      <origin rpy="0 0 0" xyz="-0.0108571428571 0 0"/>
      <geometry>
        <sphere radius="0.00475"/>
      </geometry>
      <material name="body_material"/>
    </visual>
    <visual>
      <origin rpy="0 0 0" xyz="-0.00542857142857 0 0"/>
      <geometry>
        <box size="0.0108571428571 0.000542857142857 0.000542857142857"/>
      </geometry>
    </visual>
    <collision>
      <origin rpy="0 0 0" xyz="-0.0108571428571 0 0"/>
      <geometry>
        <sphere radius="0.00475"/>
      </geometry>
    </collision>
  </link>
  <joint name="spine_lateral_joint_4" type="revolute">
    <origin rpy="1.570795 0 0" xyz="-0.0108571428571 0 0"/>
    <axis xyz="0 0 1"/>
    <parent link="spine_link_3"/>
    <child link="spine_connection_4"/>
    <dynamics damping="0.0" friction="0.0"/>
    <limit effort="30" lower="-1.570795" upper="1.570795" velocity="1.0"/>
  </joint>
  <joint name="spine_dorsal_joint_4" type="revolute">
    <origin rpy="-1.570795 0 0" xyz="0 0 0"/>
    <axis xyz="0 0 1"/>
    <parent link="spine_connection_4"/>
    <child link="spine_link_4"/>
    <dynamics damping="0.0" friction="0.0"/>
    <limit effort="30" lower="-0.39269875" upper="0.39269875" velocity="1.0"/>
  </joint>
  <link name="spine_connection_5">
    <inertial>
      <origin rpy="0 0 0" xyz="0 0 0"/>
      <mass value="4e-06"/>
      <inertia ixx="3.61e-11" ixy="0" ixz="0" iyy="3.61e-11" iyz="0" izz="3.61e-11"/>
    </inertial>
  </link>
  <link name="spine_link_5">
    <inertial>
      <origin rpy="0 0 0" xyz="-0.0108571428571 0 0"/>
      <mass value="0.000065"/>
      <inertia ixx="0.587e-09" ixy="0" ixz="0" iyy="0.587e-09" iyz="0" izz="0.587e-09"/>
    </inertial>
    <visual>
      <origin rpy="0 0 0" xyz="-0.0108571428571 0 0"/>
      <geometry>
        <sphere radius="0.00475"/>
      </geometry>
      <material name="body_material"/>
    </visual>
    <visual>
      <origin rpy="0 0 0" xyz="-0.00542857142857 0 0"/>
      <geometry>
        <box size="0.0108571428571 0.000542857142857 0.000542857142857"/>
      </geometry>
    </visual>
    <collision>
      <origin rpy="0 0 0" xyz="-0.0108571428571 0 0"/>
      <geometry>
        <sphere radius="0.00475"/>
      </geometry>
    </collision>
  </link>
  <joint name="spine_lateral_joint_5" type="revolute">
    <origin rpy="1.570795 0 0" xyz="-0.0108571428571 0 0"/>
    <axis xyz="0 0 1"/>
    <parent link="spine_link_4"/>
    <child link="spine_connection_5"/>
    <dynamics damping="0.0" friction="0.0"/>
    <limit effort="30" lower="-1.570795" upper="1.570795" velocity="1.0"/>
  </joint>
  <joint name="spine_dorsal_joint_5" type="revolute">
    <origin rpy="-1.570795 0 0" xyz="0 0 0"/>
    <axis xyz="0 0 1"/>
    <parent link="spine_connection_5"/>
    <child link="spine_link_5"/>
    <dynamics damping="0.0" friction="0.0"/>
    <limit effort="30" lower="-0.39269875" upper="0.39269875" velocity="1.0"/>
  </joint>
  <link name="right_girdle_connection_1">
    <inertial>
      <origin rpy="0 0 0" xyz="0 0 0"/>
      <mass value="4e-07"/>
      <inertia ixx="4.01111111111e-13" ixy="0" ixz="0" iyy="4.01111111111e-13" iyz="0" izz="4.01111111111e-13"/>
    </inertial>
  </link>
  <!--NOTE: currently leg joints have symmetrical limits, to avoid problems deriving from having reflected reference frames-->
  <joint name="right_girdle_abduction_joint" type="revolute">
    <origin rpy="0 0 -1.570795" xyz="0 -0.00542857142857 0"/>
    <axis xyz="0 0 1"/>
    <parent link="girdle"/>
    <child link="right_girdle_connection_1"/>
    <dynamics damping="0.0" friction="0.0"/>
    <limit effort="30" lower="-1.570795" upper="1.570795" velocity="1.0"/>
  </joint>
  <link name="right_leg">
    <inertial>
      <origin rpy="0 0 0" xyz="0.00808510638298 0 0"/>
      <mass value="4e-05"/>
      <inertia ixx="4.01111111111e-11" ixy="0" ixz="0" iyy="4.01111111111e-11" iyz="0" izz="4.01111111111e-11"/>
    </inertial>
    <visual>
      <origin rpy="0 0 0" xyz="0.00808510638298 0 0"/>
      <geometry>
        <sphere radius="0.00158333333333"/>
      </geometry>
      <material name="leg_material"/>
    </visual>
    <visual>
      <origin rpy="0 0 0" xyz="0.00404255319149 0 0"/>
      <geometry>
        <box size="0.00808510638298 0.000404255319149 0.000404255319149"/>
      </geometry>
    </visual>
    <collision>
      <origin rpy="0 0 0" xyz="0.00808510638298 0 0"/>
      <geometry>
        <sphere radius="0.00158333333333"/>
      </geometry>
    </collision>
  </link>
  <!--NOTE: currently leg joints have symmetrical limits, to avoid problems deriving from having reflected reference frames-->
  <joint name="right_girdle_flection_joint" type="revolute">
    <origin rpy="-1.570795 0 0" xyz="0 0 0"/>
    <axis xyz="0 0 1"/>
    <parent link="right_girdle_connection_1"/>
    <child link="right_leg"/>
    <dynamics damping="0.0" friction="0.0"/>
    <limit effort="30" lower="-0.01" upper="0.01" velocity="1.0"/>
  </joint>
  <link name="left_girdle_connection_1">
    <inertial>
      <origin rpy="0 0 0" xyz="0 0 0"/>
      <mass value="4e-07"/>
      <inertia ixx="4.01111111111e-13" ixy="0" ixz="0" iyy="4.01111111111e-13" iyz="0" izz="4.01111111111e-13"/>
    </inertial>
  </link>
  <!--NOTE: currently leg joints have symmetrical limits, to avoid problems deriving from having reflected reference frames-->
  <joint name="left_girdle_abduction_joint" type="revolute">
    <origin rpy="0 0 1.570795" xyz="0 0.00542857142857 0"/>
    <axis xyz="0 0 1"/>
    <parent link="girdle"/>
    <child link="left_girdle_connection_1"/>
    <dynamics damping="0.0" friction="0.0"/>
    <limit effort="30" lower="-1.570795" upper="1.570795" velocity="1.0"/>
  </joint>
  <link name="left_leg">
    <inertial>
      <origin rpy="0 0 0" xyz="0.00808510638298 0 0"/>
      <mass value="4e-05"/>
      <inertia ixx="4.01111111111e-11" ixy="0" ixz="0" iyy="4.01111111111e-11" iyz="0" izz="4.01111111111e-11"/>
    </inertial>
    <visual>
      <origin rpy="0 0 0" xyz="0.00808510638298 0 0"/>
      <geometry>
        <sphere radius="0.00158333333333"/>
      </geometry>
      <material name="leg_material"/>
    </visual>
    <visual>
      <origin rpy="0 0 0" xyz="0.00404255319149 0 0"/>
      <geometry>
        <box size="0.00808510638298 0.000404255319149 0.000404255319149"/>
      </geometry>
    </visual>
    <collision>
      <origin rpy="0 0 0" xyz="0.00808510638298 0 0"/>
      <geometry>
        <sphere radius="0.00158333333333"/>
      </geometry>
    </collision>
  </link>
  <!--NOTE: currently leg joints have symmetrical limits, to avoid problems deriving from having reflected reference frames-->
  <joint name="left_girdle_flection_joint" type="revolute">
    <origin rpy="1.570795 0 0" xyz="0 0 0"/>
    <axis xyz="0 0 1"/>
    <parent link="left_girdle_connection_1"/>
    <child link="left_leg"/>
    <dynamics damping="0.0" friction="0.0"/>
    <limit effort="30" lower="-0.01" upper="0.01" velocity="1.0"/>
  </joint>
</robot>
